Workbook

Sheet 0.안내
B2: DEEP Agent 문서 분류 레지스트리 — 데이터 대시보드
B3: Document Classification & Workflow Binding Registry
B4: 기준일 2026-06-09 · 스냅샷(마스터 갱신 시 _dashboard.py 재실행) · 범위 산업도메인 12 · 업무분류 53 · canonical 문서 154
B6: ■ 핵심 지표
B7: 총 canonical 문서 | C7: 154 | E7: 업무-문서 바인딩 | F7: 212
B8: 기존 등록 문서 | C8: 105 | E8: DEEP Agent 산출물 | F8: 4
B9: B인벤토리 추가 | C9: 49 | E9: 검증룰 보유 문서 | F9: 97
B10: 산업도메인 | C10: 12 | E10: 개인정보 포함 문서 | F10: 99
B11: 업무분류 | C11: 53 | E11: 개인정보 미포함 문서 | F11: 55
B13: ■ 개인정보 포함여부
B14: 항목 | C14: 건수 | D14: 비중
B15: 포함 | C15: 99 | D15: 0.64285714
B16: 미포함 | C16: 55 | D16: 0.35714286
B18: ■ 민감도 분포
B19: 항목 | C19: 건수 | D19: 비중
B20: 공개 | C20: 45 | D20: 0.29220779
B21: 금융정보 | C21: 42 | D21: 0.27272727
B22: 개인정보(일반) | C22: 31 | D22: 0.2012987
B23: 개인정보(민감) | C23: 24 | D23: 0.15584416
B24: 의료정보 | C24: 12 | D24: 0.077922078
B26: ■ 발급주체 분포
B27: 항목 | C27: 건수 | D27: 비중
B28: 정부/공공 | C28: 33 | D28: 0.21428571
B29: 금융기관 | C29: 12 | D29: 0.077922078
B30: 기업 | C30: 77 | D30: 0.5
B31: 의료기관 | C31: 11 | D31: 0.071428571
B32: 개인 | C32: 16 | D32: 0.1038961
B33: 법원/공증 | C33: 4 | D33: 0.025974026
B34: 보험기관 | C34: 1 | D34: 0.0064935065
B36: ■ 기능·장르 분포
B37: 항목 | C37: 건수 | D37: 비중
B38: 신청 | C38: 15 | D38: 0.097402597
B39: 계약/약정 | C39: 16 | D39: 0.1038961
B40: 증빙 | C40: 30 | D40: 0.19480519
B41: 증명 | C41: 43 | D41: 0.27922078
B42: 심사/평가 | C42: 11 | D42: 0.071428571
B43: 보고 | C43: 11 | D43: 0.071428571
B44: 의무기록 | C44: 9 | D44: 0.058441558
B45: 행정/내부 | C45: 19 | D45: 0.12337662
B47: ■ 구조유형 분포
...

Sheet 1.문서마스터
A1: 문서ID | B1: 문서명 | C1: 발급주체 | D1: 기능/장르 | E1: 구조유형 | F1: Modality | G1: 민감도 | H1: 핵심 추출필드 (베이스 스키마) | I1: 참조업무수 | J1: 비고 | K1: 개인정보 포함여부 | L1: 포함 개인정보(상세) | M1: 검증룰(문서별) | N1: 검증룰코드(VAL) | O1: 작성방식
A2: ID-01 | B2: 사업자등록증 | C2: 정부/공공 | D2: 증명 | E2: 정형양식 | F2: 스캔이미지 | G2: 금융정보 | H2: 사업자번호·상호·대표자·업태·종목·개업일 | I2: =COUNTIF('3.업무-문서매핑'!$B:$B,A2) -> 6 | J2: 다도메인 고재사용 | K2: 포함 | L2: 상호, 대표자, 사업자번호, 주소 | M2: 사업자번호 형식, 발급일 또는 등록일 유효성, 필수필드 누락, QR 또는 문서확인번호 | N2: VAL-001, VAL-002, VAL-005, VAL-013 | O2: 인쇄
A3: ID-02 | B3: 법인등기부등본(등기사항전부증명서) | C3: 법원/공증 | D3: 증명 | E3: 표중심 | F3: 전자PDF | G3: 금융정보 | H3: 법인등록번호·임원·자본금·목적·변경이력 | I3: =COUNTIF('3.업무-문서매핑'!$B:$B,A3) -> 3 | J3: 다도메인 고재사용 | K3: 포함 | L3: 법인번호, 대표자, 주소, 임원정보 | M3: 법인번호 형식, 페이지 연속성, 발행일 유효성, 대표자 추출 | N3: VAL-003, VAL-012 | O3: 인쇄
A4: ID-03 | B4: 주주명부 | C4: 기업 | D4: 행정/내부 | E4: 표중심 | F4: 전자PDF | G4: 금융정보 | H4: 주주명·지분율·주식수·취득일 | I4: =COUNTIF('3.업무-문서매핑'!$B:$B,A4) -> 2 | K4: 포함 | O4: 인쇄
A5: ID-04 | B5: 주민등록등본 | C5: 정부/공공 | D5: 증명 | E5: 정형양식 | F5: 스캔이미지 | G5: 개인정보(민감) | H5: 성명·주민번호·주소·세대구성 | I5: =COUNTIF('3.업무-문서매핑'!$B:$B,A5) -> 2 | J5: 다도메인 고재사용 | K5: 포함 | L5: 성명, 주소, 세대구성, 주민등록번호 일부 | M5: 발급일 유효성, 문서번호, 필수필드, 직인 또는 확인번호 | N5: VAL-001, VAL-002, VAL-003, VAL-009, VAL-011, VAL-013 | O5: 인쇄
A6: ID-05 | B6: 가족관계증명서 | C6: 정부/공공 | D6: 증명 | E6: 정형양식 | F6: 스캔이미지 | G6: 개인정보(민감) | H6: 본인·가족관계·생년월일 | I6: =COUNTIF('3.업무-문서매핑'!$B:$B,A6) -> 2 | J6: 다도메인 고재사용 | K6: 포함 | L6: 성명, 가족관계, 생년월일 | M6: 발급일 유효성, 문서번호, 필수필드, 직인 또는 확인번호 | N6: VAL-001, VAL-002, VAL-003, VAL-009, VAL-011, VAL-013 | O6: 인쇄
A7: ID-06 | B7: 신분증 사본(주민·면허·여권) | C7: 정부/공공 | D7: 증명 | E7: 정형양식 | F7: 스캔이미지 | G7: 개인정보(민감) | H7: 성명·생년월일·발급일·진위확인 | I7: =COUNTIF('3.업무-문서매핑'!$B:$B,A7) -> 3 | J7: 다도메인 고재사용 | K7: 포함 | L7: 성명, 주민등록번호, 주소, 사진, 생년월일, 면허번호, 여권번호, 국적 | M7: 식별번호 형식, 유효기간, 사진영역, 마스킹 | N7: VAL-002, VAL-007 | O7: 인쇄
A8: ID-11 | B8: 실소유자 확인서(AML) | C8: 기업 | D8: 심사/평가 | E8: 반정형 | F8: 전자PDF | G8: 금융정보 | H8: 실소유자·지분구조·확인근거 | I8: =COUNTIF('3.업무-문서매핑'!$B:$B,A12) -> 6 | K8: 포함 | O8: 수기
A9: ID-12 | B9: 자격증·면허증 | C9: 정부/공공 | D9: 증명 | E9: 정형양식 | F9: 스캔이미지 | G9: 개인정보(일반) | H9: 자격명·발급기관·번호·유효기간 | I9: =COUNTIF('3.업무-문서매핑'!$B:$B,A13) -> 2 | K9: 포함 | O9: 인쇄
A10: ID-13 | B10: 재직증명서 | C10: 기업 | D10: 증명 | E10: 반정형 | F10: 스캔이미지 | G10: 개인정보(일반) | H10: 성명·부서·직위·재직기간 | I10: =COUNTIF('3.업무-문서매핑'!$B:$B,A14) -> 2 | J10: 다도메인 재사용 | K10: 포함 | L10: 성명, 생년월일, 소속, 직위 | M10: 재직기간, 발급일, 직인 존재, 성명 일치 | N10: VAL-002, VAL-009 | O10: 인쇄
A11: ID-14 | B11: 경력증명서 | C11: 기업 | D11: 증명 | E11: 반정형 | F11: 스캔이미지 | G11: 개인정보(일반) | H11: 성명·경력기간·담당업무 | I11: =COUNTIF('3.업무-문서매핑'!$B:$B,A15) -> 2 | K11: 포함 | L11: 성명, 경력기간, 직무 | M11: 발급일 유효성, 문서번호, 필수필드, 직인 또는 확인번호 | N11: VAL-001, VAL-002, VAL-003, VAL-009, VAL-011, VAL-013 | O11: 인쇄
A12: FIN-01 | B12: 재무제표(재무상태표·손익계산서) | C12: 기업 | D12: 증빙 | E12: 표중심 | F12: 전자PDF | G12: 금융정보 | H12: 자산·부채·자본·매출·영업이익·당기순이익 | I12: =COUNTIF('3.업무-문서매핑'!$B:$B,A16) -> 3 | J12: 다도메인 고재사용 | K12: 미포함 | O12: 인쇄
A13: FIN-02 | B13: 부가가치세 과세표준증명원 | C13: 정부/공공 | D13: 증빙 | E13: 정형양식 | F13: 스캔이미지 | G13: 금융정보 | H13: 과세기간·과세표준·매출액 | I13: =COUNTIF('3.업무-문서매핑'!$B:$B,A17) -> 1 | K13: 포함 | L13: 사업자번호, 매출금액 | M13: 발급일 유효성, 문서번호, 필수필드, 직인 또는 확인번호 | N13: VAL-001, VAL-002, VAL-003, VAL-009, VAL-011, VAL-013 | O13: 인쇄
A14: FIN-03 | B14: 납세증명서(국세·지방세 완납) | C14: 정부/공공 | D14: 증명 | E14: 정형양식 | F14: 스캔이미지 | G14: 금융정보 | H14: 체납유무·발급일·유효기간 | I14: =COUNTIF('3.업무-문서매핑'!$B:$B,A18) -> 0 | K14: 포함 | L14: 납세자, 사업자번호, 유효기간, 주소 | M14: 발급일 유효성, 문서번호, 필수필드, 직인 또는 확인번호 | N14: VAL-001, VAL-002, VAL-003, VAL-009, VAL-011, VAL-013 | O14: 인쇄
A15: FIN-04 | B15: 4대보험 가입증명원 | C15: 정부/공공 | D15: 증명 | E15: 정형양식 | F15: 스캔이미지 | G15: 금융정보 | H15: 가입자수·가입일·사업장 | I15: =COUNTIF('3.업무-문서매핑'!$B:$B,A19) -> 4 | K15: 미포함 | O15: 인쇄
A16: FIN-05 | B16: 근로소득 원천징수영수증 | C16: 기업 | D16: 증빙 | E16: 정형양식 | F16: 스캔이미지 | G16: 개인정보(민감) | H16: 총급여·결정세액·연도 | I16: =COUNTIF('3.업무-문서매핑'!$B:$B,A20) -> 3 | J16: 가계여신·HR 재사용 | K16: 포함 | L16: 성명, 주민번호 일부, 소득, 세액 | M16: 금액 합계, 주민번호 마스킹, 귀속연도, 회사정보 | N16: VAL-004, VAL-007 | O16: 인쇄
A17: FIN-06 | B17: 소득금액증명원 | C17: 정부/공공 | D17: 증빙 | E17: 정형양식 | F17: 스캔이미지 | G17: 개인정보(민감) | H17: 소득종류·소득금액·귀속연도 | I17: =COUNTIF('3.업무-문서매핑'!$B:$B,A21) -> 1 | K17: 포함 | L17: 성명, 사업자번호, 소득 | M17: 발급일 유효성, 문서번호, 필수필드, 직인 또는 확인번호 | N17: VAL-001, VAL-002, VAL-003, VAL-009, VAL-011, VAL-013 | O17: 인쇄
A18: FIN-07 | B18: 거래실적·매출증빙 | C18: 기업 | D18: 증빙 | E18: 표중심 | F18: 전자PDF | G18: 금융정보 | H18: 거래처·거래액·기간 | I18: =COUNTIF('3.업무-문서매핑'!$B:$B,A22) -> 2 | K18: 미포함 | O18: 인쇄
A19: FIN-08 | B19: 전자세금계산서 | C19: 기업 | D19: 증빙 | E19: 정형양식 | F19: 전자PDF | G19: 금융정보 | H19: 공급가액·세액·공급자·공급받는자·작성일 | I19: =COUNTIF('3.업무-문서매핑'!$B:$B,A23) -> 1 | J19: 다도메인 고재사용 | K19: 미포함 | L19: 사업자번호, 금액, 거래처 | M19: 금액 합계, 사업자번호 형식, 승인번호, 작성일 | N19: VAL-002, VAL-004, VAL-005 | O19: 인쇄
A20: FIN-09 | B20: 지출증빙(현금영수증·영수증) | C20: 기업 | D20: 증빙 | E20: 반정형 | F20: 스캔이미지 | G20: 금융정보 | H20: 금액·가맹점·일자·항목 | I20: =COUNTIF('3.업무-문서매핑'!$B:$B,A24) -> 1 | J20: 다도메인 재사용 | K20: 미포함 | L20: 가맹점, 금액, 카드 일부번호, 식별번호 일부, 상호, 날짜 | M20: 금액 합계, 승인번호, 결제일, 날짜 | N20: VAL-002, VAL-004 | O20: 수기
A21: FIN-10 | B21: 통장 거래내역서 | C21: 금융기관 | D21: 증빙 | E21: 표중심 | F21: 전자PDF | G21: 금융정보 | H21: 거래일·적요·입출금·잔액 | I21: =COUNTIF('3.업무-문서매핑'!$B:$B,A25) -> 2 | K21: 포함 | L21: 계좌번호, 거래내역 | M21: 표 구조, 합계, 기간 | N21: VAL-004 | O21: 인쇄
A22: FIN-11 | B22: 감사보고서·결산보고서 | C22: 기업 | D22: 보고 | E22: 비정형 | F22: 전자PDF | G22: 금융정보 | H22: 감사의견·재무수치·주석 | I22: =COUNTIF('3.업무-문서매핑'!$B:$B,A26) -> 1 | K22: 미포함 | O22: 인쇄
A23: FIN-13 | B23: 급여대장·임금명세서 | C23: 기업 | D23: 행정/내부 | E23: 표중심 | F23: 전자PDF | G23: 개인정보(민감) | H23: 지급항목·공제항목·실지급액 | I23: =COUNTIF('3.업무-문서매핑'!$B:$B,A28) -> 3 | J23: ACC·HR 재사용 | K23: 포함 | L23: 성명, 급여, 공제, 계좌 가능 | M23: 표 구조, 합계, 기간 | N23: VAL-004 | O23: 인쇄
A24: FIN-14 | B24: 법인세·소득세 신고서 | C24: 기업 | D24: 보고 | E24: 정형양식 | F24: 전자PDF | G24: 금융정보 | H24: 과세표준·산출세액·신고일 | I24: =COUNTIF('3.업무-문서매핑'!$B:$B,A29) -> 2 | K24: 포함 | O24: 인쇄
A25: APP-01 | B25: 여신신청서 | C25: 개인 | D25: 신청 | E25: 정형양식 | F25: 스캔이미지 | G25: 금융정보 | H25: 신청금액·자금용도·상환계획·담보 | I25: =COUNTIF('3.업무-문서매핑'!$B:$B,A30) -> 3 | K25: 포함 | L25: 성명, 소득, 계좌, 주소 | M25: 필수필드, 서명 존재, 첨부서류, 체크박스 | N25: VAL-001, VAL-008, VAL-010 | O25: 수기
A26: APP-02 | B26: 여신거래약정서 | C26: 금융기관 | D26: 계약/약정 | E26: 반정형 | F26: 전자PDF | G26: 금융정보 | H26: 약정금액·금리·기한·특약 | I26: =COUNTIF('3.업무-문서매핑'!$B:$B,A31) -> 1 | K26: 포함 | O26: 수기
A27: APP-03 | B27: 보험청약서 | C27: 개인 | D27: 신청 | E27: 정형양식 | F27: 스캔이미지 | G27: 개인정보(민감) | H27: 피보험자·담보·보험료·고지사항 | I27: =COUNTIF('3.업무-문서매핑'!$B:$B,A32) -> 2 | K27: 포함 | O27: 수기
A28: APP-04 | B28: 보험금청구서 | C28: 개인 | D28: 신청 | E28: 정형양식 | F28: 스캔이미지 | G28: 개인정보(민감) | H28: 청구사유·청구금액·사고일·수익자 | I28: =COUNTIF('3.업무-문서매핑'!$B:$B,A33) -> 1 | K28: 포함 | L28: 피보험자, 사고정보, 계좌, 의료정보 가능 | M28: 서명 존재, 계좌번호 형식, 사고일 형식, 필수첨부, S4 검수 | N28: VAL-001, VAL-006, VAL-008, VAL-015 | O28: 수기
A29: APP-05 | B29: 인허가·보조금 신청서 | C29: 기업 | D29: 신청 | E29: 정형양식 | F29: HWP | G29: 공개 | H29: 신청항목·사업개요·신청액 | I29: =COUNTIF('3.업무-문서매핑'!$B:$B,A34) -> 1 | K29: 포함 | L29: 신청인, 사업자정보, 주소 | M29: 필수필드, 서명 존재, 첨부서류, 체크박스 | N29: VAL-001, VAL-008, VAL-010 | O29: 수기
A30: APP-06 | B30: 계약서(공공·민간) | C30: 기업 | D30: 계약/약정 | E30: 비정형 | F30: 전자PDF | G30: 공개 | H30: 계약당사자·계약금액·기간·의무사항 | I30: =COUNTIF('3.업무-문서매핑'!$B:$B,A35) -> 1 | J30: 다도메인 재사용 | K30: 포함 | L30: 당사자, 금액, 담당자 | M30: 계약기간, 금액, 서명, 자동갱신 및 위험조항 | N30: VAL-002, VAL-004, VAL-008 | O30: 수기
A31: APP-07 | B31: 근로계약서 | C31: 기업 | D31: 계약/약정 | E31: 반정형 | F31: 전자PDF | G31: 개인정보(일반) | H31: 근로자·임금·근로시간·계약기간 | I31: =COUNTIF('3.업무-문서매핑'!$B:$B,A36) -> 2 | J31: HR 재사용 | K31: 포함 | L31: 성명, 주소, 임금, 계좌 가능 | M31: 계약기간, 금액, 서명, 자동갱신 및 위험조항 | N31: VAL-002, VAL-004, VAL-008 | O31: 수기
A32: APP-08 | B32: 임대차계약서 | C32: 개인 | D32: 계약/약정 | E32: 반정형 | F32: 스캔이미지 | G32: 개인정보(일반) | H32: 임대인·임차인·보증금·차임·기간 | I32: =COUNTIF('3.업무-문서매핑'!$B:$B,A37) -> 0 | K32: 포함 | L32: 임대인, 임차인, 주소, 보증금 | M32: 계약기간, 금액, 서명, 자동갱신 및 위험조항 | N32: VAL-002, VAL-004, VAL-008 | O32: 수기
A33: APP-09 | B33: 공급·구매계약서 | C33: 기업 | D33: 계약/약정 | E33: 비정형 | F33: 전자PDF | G33: 공개 | H33: 품목·단가·납기·결제조건 | I33: =COUNTIF('3.업무-문서매핑'!$B:$B,A38) -> 1 | J33: MFG·TRD 재사용 | K33: 포함 | L33: 당사자, 금액, 담당자 | M33: 계약기간, 금액, 서명, 자동갱신 및 위험조항 | N33: VAL-002, VAL-004, VAL-008 | O33: 수기
A34: APP-10 | B34: 용역계약서 | C34: 기업 | D34: 계약/약정 | E34: 비정형 | F34: 전자PDF | G34: 공개 | H34: 용역범위·대가·기간·산출물 | I34: =COUNTIF('3.업무-문서매핑'!$B:$B,A39) -> 4 | K34: 포함 | L34: 당사자, 금액, 담당자 | M34: 계약기간, 금액, 서명, 자동갱신 및 위험조항 | N34: VAL-002, VAL-004, VAL-008 | O34: 수기
A35: APP-11 | B35: 비밀유지계약서(NDA) | C35: 기업 | D35: 계약/약정 | E35: 비정형 | F35: 전자PDF | G35: 공개 | H35: 당사자·비밀정보범위·기간 | I35: =COUNTIF('3.업무-문서매핑'!$B:$B,A40) -> 0 | K35: 포함 | L35: 당사자, 담당자 | M35: 계약기간, 금액, 서명, 자동갱신 및 위험조항 | N35: VAL-002, VAL-004, VAL-008 | O35: 수기
A36: APP-12 | B36: 약관·상품설명서 | C36: 금융기관 | D36: 계약/약정 | E36: 비정형 | F36: 전자PDF | G36: 공개 | H36: 보장내용·면책·수수료·고지 | I36: =COUNTIF('3.업무-문서매핑'!$B:$B,A41) -> 3 | K36: 미포함 | O36: 인쇄
A37: APP-13 | B37: 계좌개설신청서 | C37: 개인 | D37: 신청 | E37: 정형양식 | F37: 스캔이미지 | G37: 금융정보 | H37: 고객정보·계좌종류·실명확인 | I37: =COUNTIF('3.업무-문서매핑'!$B:$B,A42) -> 1 | K37: 포함 | L37: 성명, 연락처, 주소, 계좌정보 | M37: 필수필드, 서명 존재, 필수 체크박스, 손글씨 confidence | N37: VAL-001, VAL-008, VAL-010, VAL-014 | O37: 수기
A38: APP-14 | B38: 카드발급신청서 | C38: 개인 | D38: 신청 | E38: 정형양식 | F38: 스캔이미지 | G38: 금융정보 | H38: 신청인·소득·한도신청·동의 | I38: =COUNTIF('3.업무-문서매핑'!$B:$B,A43) -> 3 | K38: 포함 | O38: 수기
A39: CRD-01 | B39: 신용정보조회서(NICE·KCB) | C39: 기업 | D39: 심사/평가 | E39: 표중심 | F39: 전자PDF | G39: 금융정보 | H39: 신용등급·연체이력·대출현황 | I39: =COUNTIF('3.업무-문서매핑'!$B:$B,A44) -> 1 | K39: 포함 | O39: 인쇄
A40: CRD-02 | B40: 기업신용등급평가서 | C40: 기업 | D40: 심사/평가 | E40: 비정형 | F40: 전자PDF | G40: 금융정보 | H40: 신용등급·재무·비재무 평가 | I40: =COUNTIF('3.업무-문서매핑'!$B:$B,A45) -> 3 | K40: 미포함 | O40: 인쇄
...

Sheet 2.업무분류
A1: 업무ID | B1: 산업도메인 | C1: 업무명 | D1: 업무 설명 | E1: 산출물ID | F1: 입력문서 수 | G1: 필수 입력문서 수
A2: BANK-01 | B2: 금융 - 은행 (여신·신용·외환) | C2: 기업여신 심사 | D2: 기업 대출 신청에 대한 재무·신용·담보 종합 심사 | E2: RPT-02 | F2: =COUNTIFS('3.업무-문서매핑'!$A:$A,A2,'3.업무-문서매핑'!$C:$C,"입력") -> 11 | G2: =COUNTIFS('3.업무-문서매핑'!$A:$A,A2,'3.업무-문서매핑'!$C:$C,"입력",'3.업무-문서매핑'!$D:$D,"필수") -> 6
A3: BANK-02 | B3: 금융 - 은행 (여신·신용·외환) | C3: 가계여신 심사 | D3: 개인 대출 신청에 대한 소득·신용 심사 | E3: RPT-02 | F3: =COUNTIFS('3.업무-문서매핑'!$A:$A,A3,'3.업무-문서매핑'!$C:$C,"입력") -> 6 | G3: =COUNTIFS('3.업무-문서매핑'!$A:$A,A3,'3.업무-문서매핑'!$C:$C,"입력",'3.업무-문서매핑'!$D:$D,"필수") -> 5
A4: BANK-04 | B4: 금융 - 은행 (여신·신용·외환) | C4: 담보평가 | D4: 부동산·자산 담보가치 산정 및 권리 확인 | E4: - | F4: =COUNTIFS('3.업무-문서매핑'!$A:$A,A5,'3.업무-문서매핑'!$C:$C,"입력") -> 5 | G4: =COUNTIFS('3.업무-문서매핑'!$A:$A,A5,'3.업무-문서매핑'!$C:$C,"입력",'3.업무-문서매핑'!$D:$D,"필수") -> 4
A5: BANK-05 | B5: 금융 - 은행 (여신·신용·외환) | C5: KYC·AML 고객확인 | D5: 고객확인 및 실소유자 검증 | E5: RPT-08 | F5: =COUNTIFS('3.업무-문서매핑'!$A:$A,A6,'3.업무-문서매핑'!$C:$C,"입력") -> 4 | G5: =COUNTIFS('3.업무-문서매핑'!$A:$A,A6,'3.업무-문서매핑'!$C:$C,"입력",'3.업무-문서매핑'!$D:$D,"필수") -> 1
A6: BANK-07 | B6: 금융 - 은행 (여신·신용·외환) | C6: 여신 사후관리·모니터링 | D6: 약정 이후 거래·재무 변동 모니터링 | E6: RPT-07 | F6: =COUNTIFS('3.업무-문서매핑'!$A:$A,A8,'3.업무-문서매핑'!$C:$C,"입력") -> 5 | G6: =COUNTIFS('3.업무-문서매핑'!$A:$A,A8,'3.업무-문서매핑'!$C:$C,"입력",'3.업무-문서매핑'!$D:$D,"필수") -> 3
A7: SEC-T1 | B7: 금융 - 증권·자산운용 | C7: 투자상품 적합성·적정성 점검 | D7: 투자자 성향과 상품 위험도 매칭 검증 | E7: RPT-08 | F7: =COUNTIFS('3.업무-문서매핑'!$A:$A,A11,'3.업무-문서매핑'!$C:$C,"입력") -> 7 | G7: =COUNTIFS('3.업무-문서매핑'!$A:$A,A11,'3.업무-문서매핑'!$C:$C,"입력",'3.업무-문서매핑'!$D:$D,"필수") -> 3
A8: SEC-T3 | B8: 금융 - 증권·자산운용 | C8: IB 실사(due diligence) 문서검토 | D8: 투자 대상 재무·법무 실사 자료 검토 | E8: RPT-06 | F8: =COUNTIFS('3.업무-문서매핑'!$A:$A,A13,'3.업무-문서매핑'!$C:$C,"입력") -> 4 | G8: =COUNTIFS('3.업무-문서매핑'!$A:$A,A13,'3.업무-문서매핑'!$C:$C,"입력",'3.업무-문서매핑'!$D:$D,"필수") -> 3
A9: CARD-01 | B9: 금융 - 카드·여신전문 | C9: 카드 발급심사 | D9: 카드 발급 신청 소득·신용 심사 | E9: RPT-02 | F9: =COUNTIFS('3.업무-문서매핑'!$A:$A,A15,'3.업무-문서매핑'!$C:$C,"입력") -> 4 | G9: =COUNTIFS('3.업무-문서매핑'!$A:$A,A15,'3.업무-문서매핑'!$C:$C,"입력",'3.업무-문서매핑'!$D:$D,"필수") -> 2
A10: INS-01 | B10: 보험 (생명·손해) | C10: 인수심사(Underwriting) | D10: 청약 위험 평가 및 인수 여부 결정 | E10: RPT-08 | F10: =COUNTIFS('3.업무-문서매핑'!$A:$A,A17,'3.업무-문서매핑'!$C:$C,"입력") -> 4 | G10: =COUNTIFS('3.업무-문서매핑'!$A:$A,A17,'3.업무-문서매핑'!$C:$C,"입력",'3.업무-문서매핑'!$D:$D,"필수") -> 2
A11: INS-02 | B11: 보험 (생명·손해) | C11: 보험금청구 심사(Claims) | D11: 청구 서류 검증 및 지급 심사 | E11: RPT-03 | F11: =COUNTIFS('3.업무-문서매핑'!$A:$A,A18,'3.업무-문서매핑'!$C:$C,"입력") -> 4 | G11: =COUNTIFS('3.업무-문서매핑'!$A:$A,A18,'3.업무-문서매핑'!$C:$C,"입력",'3.업무-문서매핑'!$D:$D,"필수") -> 3
A12: INS-03 | B12: 보험 (생명·손해) | C12: 손해사정 | D12: 손해액 산정 및 과실 평가 | E12: RPT-03 | F12: =COUNTIFS('3.업무-문서매핑'!$A:$A,A19,'3.업무-문서매핑'!$C:$C,"입력") -> 3 | G12: =COUNTIFS('3.업무-문서매핑'!$A:$A,A19,'3.업무-문서매핑'!$C:$C,"입력",'3.업무-문서매핑'!$D:$D,"필수") -> 1
A13: INS-04 | B13: 보험 (생명·손해) | C13: 사망·장해 보험금 심사 | D13: 사망·장해 청구의 인과 및 지급 심사 | E13: RPT-03 | F13: =COUNTIFS('3.업무-문서매핑'!$A:$A,A20,'3.업무-문서매핑'!$C:$C,"입력") -> 3 | G13: =COUNTIFS('3.업무-문서매핑'!$A:$A,A20,'3.업무-문서매핑'!$C:$C,"입력",'3.업무-문서매핑'!$D:$D,"필수") -> 2
A14: INS-05 | B14: 보험 (생명·손해) | C14: 보험사기 탐지(SIU) 보조 | D14: 이상 청구 패턴 및 문서 정합성 점검 | E14: RPT-08 | F14: =COUNTIFS('3.업무-문서매핑'!$A:$A,A21,'3.업무-문서매핑'!$C:$C,"입력") -> 2 | G14: =COUNTIFS('3.업무-문서매핑'!$A:$A,A21,'3.업무-문서매핑'!$C:$C,"입력",'3.업무-문서매핑'!$D:$D,"필수") -> 1
A15: GOV-01 | B15: 공공·행정 (B2G) | C15: 인허가 심사 | D15: 인허가 신청 서류 검토 및 적합성 판단 | E15: RPT-07 | F15: =COUNTIFS('3.업무-문서매핑'!$A:$A,A22,'3.업무-문서매핑'!$C:$C,"입력") -> 3 | G15: =COUNTIFS('3.업무-문서매핑'!$A:$A,A22,'3.업무-문서매핑'!$C:$C,"입력",'3.업무-문서매핑'!$D:$D,"필수") -> 2
A16: GOV-02 | B16: 공공·행정 (B2G) | C16: 보조금·지원금 심사 | D16: 지원사업 신청 적격성 및 평가 | E16: RPT-07 | F16: =COUNTIFS('3.업무-문서매핑'!$A:$A,A23,'3.업무-문서매핑'!$C:$C,"입력") -> 3 | G16: =COUNTIFS('3.업무-문서매핑'!$A:$A,A23,'3.업무-문서매핑'!$C:$C,"입력",'3.업무-문서매핑'!$D:$D,"필수") -> 1
A17: GOV-03 | B17: 공공·행정 (B2G) | C17: 보조금 정산 검토 | D17: 집행 증빙과 정산보고서 대사 | E17: RPT-08 | F17: =COUNTIFS('3.업무-문서매핑'!$A:$A,A24,'3.업무-문서매핑'!$C:$C,"입력") -> 2 | G17: =COUNTIFS('3.업무-문서매핑'!$A:$A,A24,'3.업무-문서매핑'!$C:$C,"입력",'3.업무-문서매핑'!$D:$D,"필수") -> 1
A18: GOV-04 | B18: 공공·행정 (B2G) | C18: 조달·입찰 평가 | D18: 입찰 제안서 평가 및 적격성 심사 | E18: RPT-07 | F18: =COUNTIFS('3.업무-문서매핑'!$A:$A,A25,'3.업무-문서매핑'!$C:$C,"입력") -> 3 | G18: =COUNTIFS('3.업무-문서매핑'!$A:$A,A25,'3.업무-문서매핑'!$C:$C,"입력",'3.업무-문서매핑'!$D:$D,"필수") -> 1
A19: GOV-05 | B19: 공공·행정 (B2G) | C19: 계약 관리 | D19: 계약 체결·이행 문서 관리 | E19: - | F19: =COUNTIFS('3.업무-문서매핑'!$A:$A,A26,'3.업무-문서매핑'!$C:$C,"입력") -> 3 | G19: =COUNTIFS('3.업무-문서매핑'!$A:$A,A26,'3.업무-문서매핑'!$C:$C,"입력",'3.업무-문서매핑'!$D:$D,"필수") -> 2
A20: GOV-06 | B20: 공공·행정 (B2G) | C20: 기록물 분류·관리(BRM 연계) | D20: 공문서 기능분류 및 보존기준 매핑 | E20: - | F20: =COUNTIFS('3.업무-문서매핑'!$A:$A,A27,'3.업무-문서매핑'!$C:$C,"입력") -> 3 | G20: =COUNTIFS('3.업무-문서매핑'!$A:$A,A27,'3.업무-문서매핑'!$C:$C,"입력",'3.업무-문서매핑'!$D:$D,"필수") -> 1
A21: GOV-07 | B21: 공공·행정 (B2G) | C21: 민원 접수·처리 | D21: 민원 문서 분류 및 처리 라우팅 | E21: RPT-07 | F21: =COUNTIFS('3.업무-문서매핑'!$A:$A,A28,'3.업무-문서매핑'!$C:$C,"입력") -> 4 | G21: =COUNTIFS('3.업무-문서매핑'!$A:$A,A28,'3.업무-문서매핑'!$C:$C,"입력",'3.업무-문서매핑'!$D:$D,"필수") -> 2
... A47: HR-T4 | B47: 인사·노무 (공통) | C47: 근로계약·근태 관리 | D47: 근로계약 조건 및 근태 정리 | E47: - | F47: =COUNTIFS('3.업무-문서매핑'!$A:$A,A54,'3.업무-문서매핑'!$C:$C,"입력") -> 0 | G47: =COUNTIFS('3.업무-문서매핑'!$A:$A,A54,'3.업무-문서매핑'!$C:$C,"입력",'3.업무-문서매핑'!$D:$D,"필수") -> 0

Sheet 3.업무-문서매핑
A1: 업무ID | B1: 문서ID | C1: 방향(입력/산출) | D1: 필수여부 | E1: 업무명 | F1: 문서명
A2: BANK-01 | B2: APP-01 | C2: 입력 | D2: 필수 | E2: 기업여신 심사 | F2: 여신신청서
A3: BANK-01 | B3: ID-01 | C3: 입력 | D3: 필수 | E3: 기업여신 심사 | F3: 사업자등록증
A4: BANK-01 | B4: ID-02 | C4: 입력 | D4: 필수 | E4: 기업여신 심사 | F4: 법인등기부등본(등기사항전부증명서)
A5: BANK-01 | B5: ID-03 | C5: 입력 | D5: 선택 | E5: 기업여신 심사 | F5: 주주명부
A6: BANK-01 | B6: FIN-01 | C6: 입력 | D6: 필수 | E6: 기업여신 심사 | F6: 재무제표(재무상태표·손익계산서)
A7: BANK-01 | B7: FIN-02 | C7: 입력 | D7: 선택 | E7: 기업여신 심사 | F7: 부가가치세 과세표준증명원
A8: BANK-01 | B8: FIN-03 | C8: 입력 | D8: 필수 | E8: 기업여신 심사 | F8: 납세증명서(국세·지방세 완납)
A9: BANK-01 | B9: FIN-04 | C9: 입력 | D9: 선택 | E9: 기업여신 심사 | F9: 4대보험 가입증명원
A10: BANK-01 | B10: RPT-01 | C10: 입력 | D10: 선택 | E10: 기업여신 심사 | F10: 사업계획서·자금사용계획서
A11: BANK-01 | B11: ADM-01 | C11: 입력 | D11: 선택 | E11: 기업여신 심사 | F11: 회의록(이사회·주총)
A12: BANK-01 | B12: CRD-01 | C12: 입력 | D12: 필수 | E12: 기업여신 심사 | F12: 신용정보조회서(NICE·KCB)
... A188: HR-T4 | B188: HR-03 | C188: 입력 | D188: 선택 | E188: 근로계약·근태 관리 | F188: 근태기록·출근부

Sheet 4.Facet범례
B2: Facet 분류 축 정의
B3: 단일 트리가 아니라 직교하는 다축. 한 문서는 각 축에서 하나의 값을 갖되, 축 자체는 서로 독립이다.
B5: 발급주체 | C5: 정부/공공 · 금융기관 · 기업 · 의료기관 · 개인 · 법원/공증. 누가 발급했는가는 진위검증과 신뢰수준을 결정한다.
B6: 기능/장르 | C6: 신청 · 계약/약정 · 증빙 · 증명 · 심사/평가 · 보고 · 의무기록 · 행정/내부. 업무 내 역할을 규정하는 가장 중요한 축.
B7: 구조유형 | C7: 정형양식(고정 레이아웃) · 반정형(부분 고정) · 비정형(자유 텍스트) · 표중심. 추출 전략과 모델 선택을 좌우한다.
B8: Modality | C8: 스캔이미지 · 전자PDF · HWP · 이미지+표 혼합. 한국 특성상 HWP와 표중심 비중이 높아 OCR·VLM 파이프라인 분기를 결정한다.
B9: 민감도 | C9: 개인정보(민감) · 개인정보(일반) · 의료정보 · 금융정보 · 공개. 망분리·접근통제·마스킹 정책을 결정하는 규제 축.
B11: 분할 기준 | C11: 두 문서를 별개 canonical로 나눌지의 유일한 기준은 '그 구분이 downstream 추출·검증을 실제로 바꾸는가'이다. 같은 필드를 같은 워크플로우로 흘린다면 나누지 않는다.

Sheet 5.검증룰사전
A1: Rule ID | B1: 규칙명 | C1: 설명 | D1: 적용 대상 | E1: 심각도 | F1: 검수 트리거 | G1: 자동화 처리
A2: VAL-001 | B2: 필수필드 누락 | C2: 문서 유형별 required_fields가 비어 있으면 오류 처리합니다. | D2: 전체 문서 | E2: High | F2: 필수필드 누락 | G2: 자동 반려 또는 검수 큐
A3: VAL-002 | B3: 날짜 형식 검증 | C3: 발급일, 계약일, 진료일 등 날짜를 yyyy-mm-dd로 정규화합니다. | D3: 전체 문서 | E3: Medium | F3: 날짜 파싱 실패 | G3: 검수 큐
A4: VAL-003 | B4: 미래 발급일 금지 | C4: 발급일 또는 작성일이 처리일보다 미래이면 이상치로 표시합니다. | D4: 증명서, 계약서 | E4: Medium | F4: 미래일자 발견 | G4: 검수 큐
A5: VAL-004 | B5: 금액 합계 검증 | C5: 품목별 금액, 공급가액, 부가세, 합계금액의 산술관계를 검증합니다. | D5: 거래증빙, 영수증, 명세서 | E5: High | F5: 합계 불일치 | G5: 검수 큐
A6: VAL-005 | B6: 사업자등록번호 형식 | C6: 000-00-00000 형태 또는 숫자 10자리로 정규화합니다. | D6: 사업자·세무 문서 | E6: High | F6: 형식 불일치 | G6: 검수 큐
A7: VAL-006 | B7: 계좌번호 형식 | C7: 은행별 허용 길이와 특수문자 정규화를 적용합니다. | D7: 금융, 보험, 정산 | E7: High | F7: 계좌번호 불명확 | G7: 검수 큐
A8: VAL-007 | B8: 주민번호 마스킹 | C8: 고유식별정보는 저장 전 마스킹 또는 암호화 정책을 적용합니다. | D8: S3 이상 | E8: Critical | F8: 원문 노출 | G8: 저장 차단
A9: VAL-008 | B9: 서명 존재 여부 | C9: 서명 필수 문서에서 signature_present가 false이면 검수로 보냅니다. | D9: 신청서, 계약서, 동의서 | E9: High | F9: 서명 없음 | G9: 검수 큐
A10: VAL-009 | B10: 도장 또는 직인 존재 여부 | C10: 직인 필수 증명서와 계약서에서 seal_present를 확인합니다. | D10: 증명서, 계약서 | E10: Medium | F10: 도장 없음 | G10: 검수 큐
A11: VAL-010 | B11: 체크박스 필수동의 | C11: 필수동의 항목이 false이면 업무 처리를 중단합니다. | D11: 동의서 | E11: High | F11: 필수동의 누락 | G11: 자동 반려
A12: VAL-011 | B12: 문서 중복 탐지 | C12: 문서번호, 발급일, 핵심 필드 해시로 중복 업로드를 탐지합니다. | D12: 전체 문서 | E12: Medium | F12: 중복 의심 | G12: 중복 경고
... A16: VAL-015 | B16: S4 자동 의사결정 제한 | C16: 민감정보 문서는 자동 의사결정 또는 자동 거절에 사용하지 않습니다. | D16: 의료문서, 보험 청구 | E16: Critical | F16: S4 문서 자동처리 | G16: Human-in-the-loop

Sheet 6.문서매핑
A1: A 문서ID | B1: A 문서명 | C1: 매칭상태 | D1: B 관리ID | E1: B 문서유형 | F1: 비고
A2: ID-01 | B2: 사업자등록증 | C2: 매칭 | D2: DOC-KR-0010 | E2: 사업자등록증
A3: ID-02 | B3: 법인등기부등본(등기사항전부증명서) | C3: 매칭 | D3: DOC-KR-0011 | E3: 법인등기부등본
A4: ID-03 | B4: 주주명부 | C4: A고유(B미수록) | F4: B에 대응 문서 없음
A5: ID-04 | B5: 주민등록등본 | C5: 매칭 | D5: DOC-KR-0001 | E5: 주민등록등본
A6: ID-05 | B6: 가족관계증명서 | C6: 매칭 | D6: DOC-KR-0003 | E6: 가족관계증명서
A7: ID-06 | B7: 신분증 사본(주민·면허·여권) | C7: 매칭 | D7: DOC-KR-0006, DOC-KR-0007, DOC-KR-0008 | E7: 주민등록증 / 운전면허증 / 여권
A8: ID-11 | B8: 실소유자 확인서(AML) | C8: A고유(B미수록) | F8: B에 대응 문서 없음
A9: ID-12 | B9: 자격증·면허증 | C9: A고유(B미수록) | F9: B에 대응 문서 없음
A10: ID-13 | B10: 재직증명서 | C10: 매칭 | D10: DOC-KR-0060 | E10: 재직증명서
A11: ID-14 | B11: 경력증명서 | C11: 매칭 | D11: DOC-KR-0061 | E11: 경력증명서
A12: FIN-01 | B12: 재무제표(재무상태표·손익계산서) | C12: A고유(B미수록) | F12: B에 대응 문서 없음
A13: FIN-02 | B13: 부가가치세 과세표준증명원 | C13: 매칭 | D13: DOC-KR-0016 | E13: 부가가치세 과세표준증명
A14: FIN-03 | B14: 납세증명서(국세·지방세 완납) | C14: 매칭 | D14: DOC-KR-0017, DOC-KR-0018 | E14: 납세증명서(국세) / 지방세 납세증명서
A15: FIN-04 | B15: 4대보험 가입증명원 | C15: A고유(B미수록) | F15: B에 대응 문서 없음
A16: FIN-05 | B16: 근로소득 원천징수영수증 | C16: 매칭 | D16: DOC-KR-0062 | E16: 원천징수영수증
A17: FIN-06 | B17: 소득금액증명원 | C17: 매칭 | D17: DOC-KR-0063 | E17: 소득금액증명원
A18: FIN-07 | B18: 거래실적·매출증빙 | C18: A고유(B미수록) | F18: B에 대응 문서 없음
A19: FIN-08 | B19: 전자세금계산서 | C19: 매칭 | D19: DOC-KR-0038 | E19: 전자세금계산서
A20: FIN-09 | B20: 지출증빙(현금영수증·영수증) | C20: 매칭 | D20: DOC-KR-0045, DOC-KR-0046, DOC-KR-0047 | E20: 카드매출전표 / 현금영수증 / 간이영수증
A21: FIN-10 | B21: 통장 거래내역서 | C21: 매칭 | D21: DOC-KR-0026 | E21: 입출금거래내역서
A22: FIN-11 | B22: 감사보고서·결산보고서 | C22: A고유(B미수록) | F22: B에 대응 문서 없음
A23: FIN-13 | B23: 급여대장·임금명세서 | C23: 매칭 | D23: DOC-KR-0064 | E23: 급여명세서
A24: FIN-14 | B24: 법인세·소득세 신고서 | C24: A고유(B미수록) | F24: B에 대응 문서 없음
A25: APP-01 | B25: 여신신청서 | C25: 매칭 | D25: DOC-KR-0024 | E25: 대출신청서
A26: APP-02 | B26: 여신거래약정서 | C26: A고유(B미수록) | F26: B에 대응 문서 없음
A27: APP-03 | B27: 보험청약서 | C27: A고유(B미수록) | F27: B에 대응 문서 없음
A28: APP-04 | B28: 보험금청구서 | C28: 매칭 | D28: DOC-KR-0030 | E28: 보험금청구서
A29: APP-05 | B29: 인허가·보조금 신청서 | C29: 매칭 | D29: DOC-KR-0076 | E29: 인허가신청서
A30: APP-06 | B30: 계약서(공공·민간) | C30: 매칭 | D30: DOC-KR-0048 | E30: 용역계약서
A31: APP-07 | B31: 근로계약서 | C31: 매칭 | D31: DOC-KR-0058 | E31: 근로계약서
A32: APP-08 | B32: 임대차계약서 | C32: 매칭 | D32: DOC-KR-0066 | E32: 임대차계약서
A33: APP-09 | B33: 공급·구매계약서 | C33: 매칭 | D33: DOC-KR-0049, DOC-KR-0050 | E33: 공급계약서 / 구매계약서
A34: APP-10 | B34: 용역계약서 | C34: 매칭 | D34: DOC-KR-0048 | E34: 용역계약서
A35: APP-11 | B35: 비밀유지계약서(NDA) | C35: 매칭 | D35: DOC-KR-0051 | E35: NDA
A36: APP-12 | B36: 약관·상품설명서 | C36: A고유(B미수록) | F36: B에 대응 문서 없음
A37: APP-13 | B37: 계좌개설신청서 | C37: 매칭 | D37: DOC-KR-0020 | E37: 계좌개설신청서
A38: APP-14 | B38: 카드발급신청서 | C38: A고유(B미수록) | F38: B에 대응 문서 없음
A39: CRD-01 | B39: 신용정보조회서(NICE·KCB) | C39: A고유(B미수록) | F39: B에 대응 문서 없음
A40: CRD-02 | B40: 기업신용등급평가서 | C40: A고유(B미수록) | F40: B에 대응 문서 없음
...
